Workbook

Sheet CODIGO
A1: PROVEEDOR | B1: CODIGO | C1: CARACTERISTICA | D1: TT UNIDADES
B2: DAMA ABRIGO | C2: 8 BOTONES C /CAPUCHA | D2: =ABRIGO!M5 -> 9
A3: SCAREM | B3: DAMA ABRIGO | D3: =ABRIGO!M8 -> 11
A4: KATY | B4: DAMA ABRIGO | C4: LARGO C/PELUCHE 4 B | D4: =ABRIGO!M18 -> 36
B5: DAMA ABRIGO | C5: CORTO | D5: =ABRIGO!M19 -> 1
B6: DAMA CHAMARRA | C6: CORTA | D6: =1 -> 1 | E6: =SUM(D2:D6) -> 58
B7: ABRIGO CABALLERO | C7: LARGO | D7: =ABRIGO!M21 -> 1
A8: VARCORT | B8: ABRIGO CABALLERO | C8: CORTO | D8: =ABRIGO!M22 -> 1 | E8: =D7+D8 -> 2
A9: VARCORT | B9: BLAZER CABALLERO | C9: CORTO | D9: =ABRIGO!M23 -> 8
A10: VARCORT | B10: BLAZER CABALLERO | C10: CORTO | D10: =ABRIGO!M24 -> 3 | E10: =D9+D10 -> 11
B11: ABRIGO NIÑA | D11: =ABRIGO!I37 -> 10 | E11: =D11 -> 10 | F11: =E6+E8+E10+E11 -> 81
A12: ANNY | B12: 2500 | C12: 3/4 SACO | D12: =SACO!K6 -> 16
A13: ARY | B13: ONDAS ML | C13: ONDAS ML SACO | D13: =SACO!K11 -> 20 | E13: =D12+D13 -> 36
A14: ARY | B14: 3000 | C14: CHALECO TELA LISO | D14: =CHALECO!Q13 -> 29
A15: SUPER POPNTI | B15: 4029 | C15: CHALECO TELA ESTAMPADO | D15: =CHALECO!Q14 -> 6 | E15: =D14+D15 -> 35 | F15: =E13+E15 -> 71
A16: VARIOS | B16: SUETER | C16: UNITALLA XL | D16: ='SUETER UNITALLA XL '!G276 -> 359
A17: VARIOS | B17: SUETER | C17: CH G | D17: ='SUETER CH G'!G42 -> 75 | E17: =D16+D17 -> 434
A18: REGIS | B18: COORDINADO | C18: VARIOS BLUSA/SUETER | D18: ='BLUSA SUETER COORD'!H10 -> 24
A19: TIMIDOS | B19: COORDINADO | C19: CALADO BLUSA/SUETER | D19: ='BLUSA SUETER COORD'!G20 -> 16
A20: MONJES | B20: COORDINADO | C20: ='BLUSA SUETER COORD'!C21 -> MONJES BLUS/SUETER | D20: ='BLUSA SUETER COORD'!G34 -> 14
A21: ODRE | B21: COORDINADO | C21: BORDADO BLUS/SUETER | D21: ='BLUSA SUETER COORD'!G39 -> 5 | E21: =D18+D19+D20+D21 -> 59 | F21: =E21 -> 59
A22: CAROL | B22: CAROL 01 | C22: FALDA C/HOJAS | D22: ='FALDA TALLAS'!P2 -> 12
A23: SCAREN | B23: SCAREN 01 | C23: FALDA PRETINA | D23: ='FALDA TALLAS'!P23 -> 259 | E23: =D22+D23 -> 271
A24: EVIER | B24: EVIER 01 | C24: FALDA PELO CONEJO | D24: ='UNITALLA FALVEST'!G13 -> 27 | E24: =D22+D23+D24 -> 298
A25: SEX | B25: 203 | C25: VESTIDO TABLEADO | D25: ='UNITALLA FALVEST'!G23 -> 12
A26: SEX | B26: 178 | C26: VESTIDO CUADROS | D26: ='UNITALLA FALVEST'!G29 -> 7
A27: MILEORE | B27: 2537 | C27: VESTIDO 2 BOTONES HOMBRO | D27: ='UNITALLA FALVEST'!G33 -> 4
A28: DOMIL | C28: VESTIDO 2 BOTONES MANGA | D28: ='UNITALLA FALVEST'!G35 -> 2 | E28: =SUM(D25:D28) -> 25
A29: JESSICA | B29: VARIOS | C29: VESTIDO C/SACO | D29: ='COORD TELA TALLAS'!Q22 -> 76
A30: JESSICA | B30: 1922 | C30: FALDA BLUSA C/ SACO | D30: ='COORD TELA TALLAS'!P25 -> 9 | E30: =D29+D30 -> 85
D31: =SUM(D22:D30) -> 408 | E31: =E24+E28+E30 -> 408
C33: GENERAL
A34: ABRIGOS SUETER VESTIDO FALDA COORDINADOS CARDIGAN CHALECOS | D34: =D31 -> 408
C35: BLUSAS | D35: ='[1]CODIGO 00'!$E$104 -> 1996
C36: PANTALONES | D36: =[2]CODIGO!$E$21 -> 3238
D37: =D34+D35+D36 -> 5642

Sheet ABRIGO
A1: CODIGO | B1: COLOR | C1: 28 | D1: 30 | E1: 32 | F1: 34 | G1: 36 | H1: 38 | I1: 40 | J1: 42 | K1: 44 | L1: TT UNIDADES
A2: 8 BOTONES C /CAPUCHA | B2: NEGRO | C2: 1 | D2: 0 | E2: 0 | F2: 1 | G2: 1 | H2: 0 | I2: 0 | J2: 0 | K2: 0 | L2: =SUM(C2:K2) -> 3
A3: 8 BOTONES C /CAPUCHA | B3: MARINO | C3: 0 | D3: 1 | E3: 1 | F3: 0 | G3: 0 | H3: 0 | I3: 0 | J3: 0 | K3: 0 | L3: =SUM(C3:K3) -> 2
A4: 8 BOTONES C /CAPUCHA | B4: ROJO | C4: 0 | D4: 0 | E4: 0 | F4: 1 | G4: 1 | H4: 0 | I4: 0 | J4: 0 | K4: 0 | L4: =SUM(C4:K4) -> 2
A5: 8 BOTONES C /CAPUCHA | B5: HUESO | C5: 0 | D5: 0 | E5: 1 | F5: 0 | G5: 1 | H5: 0 | I5: 0 | J5: 0 | K5: 0 | L5: =SUM(C5:K5) -> 2 | M5: =L2+L3+L4+L5 -> 9
A6: SCAREM | B6: NEGRO | C6: 0 | D6: 0 | E6: 0 | F6: 0 | G6: 4 | H6: 4 | I6: 0 | J6: 0 | K6: 0 | L6: =SUM(C6:K6) -> 8
A7: SCAREM | B7: MARINO | C7: 0 | D7: 0 | E7: 0 | F7: 0 | G7: 1 | H7: 0 | I7: 0 | J7: 0 | K7: 0 | L7: =SUM(C7:K7) -> 1
A8: SCAREM | B8: ARENA | C8: 0 | D8: 0 | E8: 0 | F8: 1 | G8: 0 | H8: 1 | I8: 0 | J8: 0 | K8: 0 | L8: =SUM(C8:K8) -> 2 | M8: =L6+L7+L8 -> 11
A9: KATY LARGO C/PELUCHE 4 B | B9: NEGRO | C9: 0 | D9: 0 | E9: 1 | F9: 0 | G9: 2 | H9: 3 | I9: 1 | J9: 1 | K9: 1 | L9: =SUM(C9:K9) -> 9
A10: KATY LARGO C/PELUCHE 4 B | B10: MOSTAZA | C10: 0 | D10: 0 | E10: 1 | F10: 5 | G10: 0 | H10: 0 | I10: 0 | J10: 0 | K10: 0 | L10: =SUM(C10:K10) -> 6
A11: KATY LARGO C/PELUCHE 4 B | B11: CAMEL | C11: 0 | D11: 0 | E11: 1 | F11: 0 | G11: 1 | H11: 0 | I11: 1 | J11: 1 | K11: 0 | L11: =SUM(C11:K11) -> 4
A12: KATY LARGO C/PELUCHE 4 B | B12: CAFE | C12: 0 | D12: 0 | E12: 1 | F12: 1 | G12: 1 | H12: 0 | I12: 0 | J12: 0 | K12: 0 | L12: =SUM(C12:K12) -> 3
A13: KATY LARGO C/PELUCHE 4 B | B13: ROJO | C13: 0 | D13: 0 | E13: 0 | F13: 1 | G13: 2 | H13: 2 | I13: 1 | J13: 0 | K13: 0 | L13: =SUM(C13:K13) -> 6
A14: KATY LARGO C/PELUCHE 4 B | B14: MARINO | C14: 0 | D14: 0 | E14: 0 | F14: 1 | G14: 0 | H14: 0 | I14: 0 | J14: 0 | K14: 0 | L14: =SUM(C14:K14) -> 1
A15: KATY LARGO C/PELUCHE 4 B | B15: PALO | C15: 0 | D15: 0 | E15: 0 | F15: 1 | G15: 0 | H15: 0 | I15: 0 | J15: 0 | K15: 0 | L15: =SUM(C15:K15) -> 1
A16: KATY LARGO C/PELUCHE 4 B | B16: VINO | C16: 0 | D16: 0 | E16: 0 | F16: 3 | G16: 0 | H16: 0 | I16: 0 | J16: 0 | K16: 0 | L16: =SUM(C16:K16) -> 3
A17: KATY LARGO C/PELUCHE 4 B | B17: ARENA | C17: 0 | D17: 0 | E17: 0 | F17: 0 | G17: 1 | H17: 0 | I17: 1 | J17: 0 | K17: 0 | L17: =SUM(C17:K17) -> 2
A18: KATY LARGO C/PELUCHE 4 B | B18: GRIS | C18: 0 | D18: 0 | E18: 0 | F18: 0 | G18: 0 | H18: 0 | I18: 0 | J18: 0 | K18: 1 | L18: =SUM(C18:K18) -> 1 | M18: =SUM(L9:L18) -> 36
A19: CORTO | B19: MORADO | C19: 0 | D19: 1 | E19: 0 | F19: 0 | G19: 0 | H19: 0 | I19: 0 | J19: 0 | K19: 0 | L19: =SUM(C19:K19) -> 1 | M19: =L19 -> 1 | N19: =M5+M8+M18+M19 -> 57
A20: CORTO CHAMARRA | B20: NEGRO | C20: 0 | D20: 0 | E20: 1 | F20: 0 | G20: 0 | H20: 0 | I20: 0 | J20: 0 | K20: 0 | L20: =SUM(C20:K20) -> 1 | M20: =L20 -> 1
A21: CABALLERO LARGO | B21: MARINO | C21: 0 | D21: 0 | E21: 0 | F21: 0 | G21: 1 | H21: 0 | I21: 0 | J21: 0 | K21: 0 | L21: =SUM(C21:K21) -> 1 | M21: =L21 -> 1
A22: VALCORT CORTO CAB | B22: CAFE | C22: 0 | D22: 0 | E22: 0 | F22: 1 | G22: 0 | H22: 0 | I22: 0 | J22: 0 | K22: 0 | L22: =SUM(C22:K22) -> 1 | M22: =L22 -> 1
A23: BLAZER LANA CAB | B23: BEIGE | C23: 1 | D23: 0 | E23: 4 | F23: 3 | G23: 0 | H23: 0 | I23: 0 | J23: 0 | K23: 0 | L23: =SUM(C23:K23) -> 8 | M23: =L23 -> 8
A24: BLAZER LANA CAB | B24: NEGRO | C24: 0 | D24: 0 | E24: 1 | F24: 2 | G24: 0 | H24: 0 | I24: 0 | J24: 0 | K24: 0 | L24: =SUM(C24:K24) -> 3 | M24: =L24 -> 3
C25: 0 | D25: 0 | E25: 0 | F25: 0 | G25: 0 | H25: 0 | I25: 0 | J25: 0 | K25: 0 | L25: =SUM(C25:K25) -> 0 | N25: =L21+L22+L23+L24 -> 13
C26: =SUM(C2:C25) -> 2 | D26: =SUM(D2:D25) -> 2 | E26: =SUM(E2:E25) -> 12 | F26: =SUM(F2:F25) -> 21 | G26: =SUM(G2:G25) -> 16 | H26: =SUM(H2:H25) -> 10 | I26: =SUM(I2:I25) -> 4 | J26: =SUM(J2:J25) -> 2 | ... L26: =SUM(L2:L25) -> 71
A31: CODIGO | B31: COLOR | C31: 6 | D31: 8 | E31: 10 | F31: 12 | G31: 14 | H31: 16 | I31: TT UNIDADES
A32: NIÑA 8 BOTONES | B32: PALO | C32: 1 | D32: 0 | E32: 1 | F32: 0 | G32: 0 | H32: 1 | I32: =SUM(C32:H32) -> 3
A33: NIÑA 8 BOTONES | B33: BLANCO | C33: 0 | D33: 0 | E33: 0 | F33: 1 | G33: 0 | H33: 0 | I33: =SUM(C33:H33) -> 1
A34: NIÑA 8 BOTONES | B34: ROJO | C34: 1 | D34: 0 | E34: 0 | F34: 1 | G34: 1 | H34: 0 | I34: =SUM(C34:H34) -> 3
A35: NIÑA 8 BOTONES | B35: MOSTAZA | C35: 0 | D35: 0 | E35: 0 | F35: 0 | G35: 0 | H35: 1 | I35: =SUM(C35:H35) -> 1
A36: NIÑA 8 BOTONES | B36: MARINO | C36: 0 | D36: 0 | E36: 0 | F36: 1 | G36: 0 | H36: 1 | I36: =SUM(C36:H36) -> 2 | J36: =I32+I33+I34+I35+I36 -> 10
C37: =SUM(C32:C36) -> 2 | D37: =SUM(D32:D36) -> 0 | E37: =SUM(E32:E36) -> 1 | F37: =SUM(F32:F36) -> 3 | G37: =SUM(G32:G36) -> 1 | H37: =SUM(H32:H36) -> 3 | I37: =SUM(I32:I36) -> 10

Sheet SACO
A1: PROVEEDOR | B1: CODIGO | C1: CARACTERISTICA | D1: COLOR | E1: 30 | F1: 32 | G1: 34 | H1: 36 | I1: 38 | J1: TT UNIDADES
A2: ANNY | B2: 2500 | C2: 3/4 SACO | D2: BLANCO | E2: 0 | F2: 1 | G2: 0 | H2: 1 | I2: 0 | J2: =SUM(E2:I2) -> 2
A3: ANNY | B3: 2500 | C3: 3/4 SACO | D3: NEGRO | E3: 0 | F3: 1 | G3: 0 | H3: 1 | I3: 0 | J3: =SUM(E3:I3) -> 2
A4: ANNY | B4: 2500 | C4: 3/4 SACO | D4: MARINO | E4: 0 | F4: 2 | G4: 2 | H4: 2 | I4: 1 | J4: =SUM(E4:I4) -> 7
A5: ANNY | B5: 2500 | C5: 3/4 SACO | D5: KELLY | E5: 0 | F5: 1 | G5: 1 | H5: 1 | I5: 0 | J5: =SUM(E5:I5) -> 3
A6: ANNY | B6: 2500 | C6: 3/4 SACO | D6: BUGAMBILIA | E6: 0 | F6: 0 | G6: 1 | H6: 1 | I6: 0 | J6: =SUM(E6:I6) -> 2 | K6: =J2+J3+J4+J5+J6 -> 16
A7: ARY | C7: ONDAS ML | D7: NEGRO | E7: 0 | F7: 2 | G7: 0 | H7: 1 | I7: 1 | J7: =SUM(E7:I7) -> 4
A8: ARY | C8: ONDAS ML | D8: MARINO | E8: 0 | F8: 1 | G8: 3 | H8: 2 | I8: 2 | J8: =SUM(E8:I8) -> 8
A9: ARY | C9: ONDAS ML | D9: CAFE | E9: 0 | F9: 1 | G9: 1 | H9: 1 | I9: 1 | J9: =SUM(E9:I9) -> 4
A10: ARY | C10: ONDAS ML | D10: BLANCO | E10: 0 | F10: 1 | G10: 2 | H10: 0 | I10: 0 | J10: =SUM(E10:I10) -> 3
A11: ARY | C11: ONDAS ML | D11: GRIS | E11: 0 | F11: 0 | G11: 1 | H11: 0 | I11: 0 | J11: =SUM(E11:I11) -> 1 | K11: =J7+J8+J9+J10+J11 -> 20
E12: =SUM(E2:E11) -> 0 | F12: =SUM(F2:F11) -> 10 | G12: =SUM(G2:G11) -> 11 | H12: =SUM(H2:H11) -> 10 | I12: =SUM(I2:I11) -> 5 | J12: =SUM(J2:J11) -> 36

Sheet CHALECO
A1: PROVEEDOR | B1: CODIGO | C1: CARACTERISTICA | D1: COLOR | E1: 28 | F1: 30 | G1: 32 | H1: 34 | I1: 36 | J1: 38 | K1: 40 | L1: 42 | M1: 44 | N1: 46 | O1: 48 | P1: TT UNIDADES
B2: 3000 | C2: CHALECO TELA | D2: AJEDREZ B/N | E2: 0 | F2: 0 | G2: 0 | H2: 0 | I2: 0 | J2: 2 | K2: 1 | P2: =SUM(E2:O2) -> 3 | Q2: =P2 -> 3
B3: 3000 | C3: CHALECO TELA | D3: CHEDRON | E3: 0 | F3: 0 | G3: 0 | H3: 1 | I3: 0 | J3: 1 | K3: 0 | L3: 0 | M3: 0 | N3: 0 | O3: 0 | P3: =SUM(E3:O3) -> 2
B4: 3000 | C4: CHALECO TELA | D4: BLANCO | E4: 0 | F4: 0 | G4: 0 | H4: 1 | I4: 1 | J4: 0 | K4: 0 | L4: 0 | M4: 0 | N4: 0 | O4: 0 | P4: =SUM(E4:O4) -> 2
B5: 3000 | C5: CHALECO TELA | D5: NEGRO | E5: 0 | F5: 0 | G5: 0 | H5: 0 | I5: 2 | J5: 0 | K5: 0 | L5: 0 | M5: 0 | N5: 0 | O5: 0 | P5: =SUM(E5:O5) -> 2
B6: 3000 | C6: CHALECO TELA | D6: MARINO | E6: 0 | F6: 0 | G6: 0 | H6: 1 | I6: 1 | J6: 1 | K6: 2 | L6: 0 | M6: 0 | N6: 0 | O6: 0 | P6: =SUM(E6:O6) -> 5
B7: 3000 | C7: CHALECO TELA | D7: FUCSIA | E7: 0 | F7: 0 | G7: 0 | H7: 1 | I7: 1 | J7: 0 | K7: 1 | L7: 0 | M7: 0 | N7: 0 | O7: 0 | P7: =SUM(E7:O7) -> 3
B8: 3000 | C8: CHALECO TELA | D8: BEIGE | E8: 0 | F8: 0 | G8: 0 | H8: 1 | I8: 1 | J8: 0 | K8: 0 | L8: 0 | M8: 0 | N8: 0 | O8: 0 | P8: =SUM(E8:O8) -> 2
B9: 3000 | C9: CHALECO TELA | D9: VINO | E9: 0 | F9: 0 | G9: 0 | H9: 1 | I9: 1 | J9: 1 | K9: 1 | L9: 0 | M9: 0 | N9: 0 | O9: 0 | P9: =SUM(E9:O9) -> 4
B10: 3000 | C10: CHALECO TELA | D10: CAMOTE | E10: 0 | F10: 0 | G10: 0 | H10: 1 | I10: 1 | J10: 1 | K10: 1 | L10: 0 | M10: 0 | N10: 0 | O10: 0 | P10: =SUM(E10:O10) -> 4
B11: 3000 | C11: CHALECO TELA | D11: MILITAR | E11: 0 | F11: 0 | G11: 0 | H11: 1 | I11: 1 | J11: 0 | K11: 0 | L11: 0 | M11: 0 | N11: 0 | O11: 0 | P11: =SUM(E11:O11) -> 2
B12: 3000 | C12: CHALECO TELA | D12: PALO | E12: 0 | F12: 0 | G12: 0 | H12: 1 | I12: 0 | J12: 0 | K12: 1 | L12: 0 | M12: 0 | N12: 0 | O12: 0 | P12: =SUM(E12:O12) -> 2
B13: 3000 | C13: CHALECO TELA | D13: LILA | E13: 0 | F13: 0 | G13: 0 | H13: 1 | I13: 0 | J13: 0 | K13: 0 | L13: 0 | M13: 0 | N13: 0 | O13: 0 | P13: =SUM(E13:O13) -> 1 | Q13: =SUM(P3:P13) -> 29
B14: 4029 | C14: TELA SUPER PONTI | D14: NEGRO ESTAMPADO | E14: 0 | F14: 0 | G14: 0 | H14: 2 | I14: 2 | J14: 2 | K14: 0 | L14: 0 | M14: 0 | N14: 0 | O14: 0 | P14: =SUM(E14:O14) -> 6 | Q14: =P14 -> 6
E15: 0 | F15: 0 | G15: 0 | H15: 0 | I15: 0 | J15: 0 | K15: 0 | L15: 0 | M15: 0 | N15: 0 | O15: 0 | P15: =SUM(E15:O15) -> 0
E16: =SUM(E2:E15) -> 0 | F16: =SUM(F2:F15) -> 0 | G16: =SUM(G2:G15) -> 0 | H16: =SUM(H2:H15) -> 12 | I16: =SUM(I2:I15) -> 11 | J16: =SUM(J2:J15) -> 8 | K16: =SUM(K2:K15) -> 7 | L16: =SUM(L2:L15) -> 0 | ... P16: =SUM(P2:P15) -> 38
B35: CODIGO | D35: COLOR | E35: M | F35: G | G35: XL | H35: TT UNIDADES
B36: P´BASIC LUZ | D36: NEGRO | E36: 0 | F36: 3 | G36: 4 | H36: =SUM(E36:G36) -> 7
B37: P´BASIC LUZ | D37: FUCSIA | E37: 0 | F37: 1 | G37: 0 | H37: =SUM(E37:G37) -> 1
B38: P´BASIC LUZ | D38: PALO | E38: 0 | F38: 0 | G38: 1 | H38: =SUM(E38:G38) -> 1
E39: =E36+E37+E38 -> 0 | F39: =F36+F37+F38 -> 4 | G39: =G36+G37+G38 -> 5 | H39: =H36+H37+H38 -> 9

Sheet SUETER UNITALLA XL 
A1: PROVEEDOR | B1: CODIGO | C1: CARACTERISTICA | D1: COLOR | E1: UNITALLA | F1: XL | G1: TT UNIDADES
A2: EVIER | B2: SPORT 3/4 | C2: SPORT 3/4 | D2: NEGRO | E2: 2 | F2: 0 | G2: =SUM(E2:F2) -> 2
A3: EVIER | B3: SPORT 3/4 | C3: SPORT 3/4 | D3: NEGRO JASPEADO | E3: 1 | F3: 0 | G3: =SUM(E3:F3) -> 1
A4: EVIER | B4: SPORT 3/4 | C4: SPORT 3/4 | D4: MARINO | E4: 1 | F4: 0 | G4: =SUM(E4:F4) -> 1
A5: EVIER | B5: SPORT 3/4 | C5: SPORT 3/4 | D5: GRIS CLARO | E5: 1 | F5: 0 | G5: =SUM(E5:F5) -> 1
A6: EVIER | B6: SPORT 3/4 | C6: SPORT 3/4 | D6: CIELO | E6: 1 | F6: 0 | G6: =SUM(E6:F6) -> 1
A7: EVIER | B7: SPORT 3/4 | C7: SPORT 3/4 | D7: CHEDRON | E7: 1 | F7: 0 | G7: =SUM(E7:F7) -> 1
A8: EVIER | B8: SPORT 3/4 | C8: SPORT 3/4 | D8: BEIGE | E8: 1 | F8: 0 | G8: =SUM(E8:F8) -> 1
A9: EVIER | B9: SPORT 3/4 | C9: SPORT 3/4 | D9: VINO | E9: 1 | F9: 0 | G9: =SUM(E9:F9) -> 1 | H9: =SUM(G2:G9) -> 9
A10: EVIER | B10: SPORT ML | C10: SPORT ML | D10: NEGRO | E10: 1 | F10: 0 | G10: =SUM(E10:F10) -> 1
A11: EVIER | B11: SPORT ML | C11: SPORT ML | D11: GRIS CLARO | E11: 1 | F11: 0 | G11: =SUM(E11:F11) -> 1
A12: EVIER | B12: SPORT ML | C12: SPORT ML | D12: PALO | E12: 1 | F12: 0 | G12: =SUM(E12:F12) -> 1
A13: EVIER | B13: SPORT ML | C13: SPORT ML | D13: LILA | E13: 1 | F13: 0 | G13: =SUM(E13:F13) -> 1
A14: EVIER | B14: SPORT ML | C14: SPORT ML | D14: CIELO | E14: 1 | F14: 0 | G14: =SUM(E14:F14) -> 1
A15: EVIER | B15: SPORT ML | C15: SPORT ML | D15: OXFORD | E15: 1 | F15: 0 | G15: =SUM(E15:F15) -> 1
A16: EVIER | B16: SPORT ML | C16: SPORT ML | D16: MOKA | E16: 1 | F16: 0 | G16: =SUM(E16:F16) -> 1
A17: EVIER | B17: SPORT ML | C17: SPORT ML | D17: ROSA | E17: 1 | F17: 0 | G17: =SUM(E17:F17) -> 1
A18: EVIER | B18: SPORT ML | C18: SPORT ML | D18: CHEDRON | E18: 1 | F18: 0 | G18: =SUM(E18:F18) -> 1 | H18: =SUM(G10:G18) -> 9
A19: EVIER | B19: C-REDND 3/4 | C19: C-REDND 3/4 | D19: MILITAR | E19: 3 | F19: 0 | G19: =SUM(E19:F19) -> 3
A20: EVIER | B20: C-REDND 3/4 | C20: C-REDND 3/4 | D20: SALMON | E20: 1 | F20: 2 | G20: =SUM(E20:F20) -> 3
A21: EVIER | B21: C-REDND 3/4 | C21: C-REDND 3/4 | D21: CEMENTO | E21: 1 | F21: 2 | G21: =SUM(E21:F21) -> 3
A22: EVIER | B22: C-REDND 3/4 | C22: C-REDND 3/4 | D22: PISTACHE | E22: 0 | F22: 4 | G22: =SUM(E22:F22) -> 4
A23: EVIER | B23: C-REDND 3/4 | C23: C-REDND 3/4 | D23: MARINO | E23: 3 | F23: 2 | G23: =SUM(E23:F23) -> 5
A24: EVIER | B24: C-REDND 3/4 | C24: C-REDND 3/4 | D24: NEGRO | E24: 1 | F24: 5 | G24: =SUM(E24:F24) -> 6
A25: EVIER | B25: C-REDND 3/4 | C25: C-REDND 3/4 | D25: CAKI | E25: 1 | F25: 0 | G25: =SUM(E25:F25) -> 1
A26: EVIER | B26: C-REDND 3/4 | C26: C-REDND 3/4 | D26: ROJO | E26: 1 | F26: 2 | G26: =SUM(E26:F26) -> 3
A27: EVIER | B27: C-REDND 3/4 | C27: C-REDND 3/4 | D27: GRIS CLARO | E27: 2 | F27: 2 | G27: =SUM(E27:F27) -> 4
A28: EVIER | B28: C-REDND 3/4 | C28: C-REDND 3/4 | D28: CIELO | E28: 0 | F28: 2 | G28: =SUM(E28:F28) -> 2
A29: EVIER | B29: C-REDND 3/4 | C29: C-REDND 3/4 | D29: BLANCO | E29: 5 | F29: 3 | G29: =SUM(E29:F29) -> 8
A30: EVIER | B30: C-REDND 3/4 | C30: C-REDND 3/4 | D30: LILA | E30: 0 | F30: 2 | G30: =SUM(E30:F30) -> 2
... A34: EVIER | B34: C-REDND 3/4 | C34: C-REDND 3/4 | D34: VINO | E34: 0 | F34: 2 | G34: =SUM(E34:F34) -> 2
A35: EVIER | B35: C-REDND 3/4 | C35: C-REDND 3/4 | D35: OXFORD | E35: 0 | F35: 2 | G35: =SUM(E35:F35) -> 2 | H35: =SUM(G19:G35) -> 57
A36: MELANI | B36: CHALECO | C36: ROMBOS | D36: NEGRO | E36: 1 | F36: 0 | G36: =SUM(E36:F36) -> 1
A37: MELANI | B37: CHALECO | C37: ROMBOS | D37: CIELO | E37: 1 | F37: 0 | G37: =SUM(E37:F37) -> 1
A38: MELANI | B38: CHALECO | C38: ROMBOS | D38: MARINO | E38: 1 | F38: 0 | G38: =SUM(E38:F38) -> 1
A39: MELANI | B39: CHALECO | C39: LADRILLO | D39: NEGRO | E39: 1 | F39: 0 | G39: =SUM(E39:F39) -> 1
A40: MELANI | B40: CHALECO | C40: LISO | D40: HUESO | E40: 1 | F40: 0 | G40: =SUM(E40:F40) -> 1
A41: MELANI | B41: CHALECO | C41: LISO | D41: LILA | E41: 1 | F41: 0 | G41: =SUM(E41:F41) -> 1
A42: MELANI | B42: CHALECO | C42: LISO | D42: BEIGE | E42: 1 | F42: 0 | G42: =SUM(E42:F42) -> 1
A43: MELANI | B43: CHALECO | C43: LISO | D43: ROJO | E43: 1 | F43: 0 | G43: =SUM(E43:F43) -> 1
...

Sheet BLUSA SUETER COORD
A1: PROVEEDOR | B1: CODIGO | C1: CARACTERISTICA | D1: COLOR | E1: UNITALLA | F1: TT UNIDADES
A2: REGIS | C2: ESPIGA BLUSA/SUETER | D2: CAMEL | E2: 5 | F2: =SUM(E2:E2) -> 5
A3: REGIS | C3: ESPIGA BLUSA/SUETER | D3: ROSA | E3: 3 | F3: =SUM(E3:E3) -> 3
A4: REGIS | C4: ESPIGA BLUSA/SUETER | D4: CHEDRON | E4: 2 | F4: =SUM(E4:E4) -> 2
A5: REGIS | C5: ESPIGA BLUSA/SUETER | D5: NEGRO | E5: 5 | F5: =SUM(E5:E5) -> 5
A6: REGIS | C6: ESPIGA BLUSA/SUETER | D6: PIZARRA | E6: 2 | F6: =SUM(E6:E6) -> 2
A7: REGIS | C7: ESPIGA BLUSA/SUETER | D7: MARINO | E7: 3 | F7: =SUM(E7:E7) -> 3 | G7: =SUM(F2:F7) -> 20
A8: REGIS | C8: PATA BLUSA/SUETER | D8: PATA GRIS | E8: 2 | F8: =SUM(E8:E8) -> 2 | G8: =F8 -> 2
A9: REGIS | C9: LISO BLUSA/SUETER | D9: GRIS | E9: 1 | F9: =SUM(E9:E9) -> 1
A10: REGIS | C10: LISO BLUSA/SUETER | D10: OLIVO | E10: 1 | F10: =SUM(E10:E10) -> 1 | G10: =SUM(F9:F10) -> 2 | H10: =G7+G8+G10 -> 24
A11: TIMIDOS | C11: CALADO BLUSA/SUETER | D11: NEGRO | E11: 1 | F11: =SUM(E11:E11) -> 1
A12: TIMIDOS | C12: CALADO BLUSA/SUETER | D12: MARINO | E12: 2 | F12: =SUM(E12:E12) -> 2
A13: TIMIDOS | C13: CALADO BLUSA/SUETER | D13: OXFORD | E13: 2 | F13: =SUM(E13:E13) -> 2
A14: TIMIDOS | C14: CALADO BLUSA/SUETER | D14: CAKI | E14: 2 | F14: =SUM(E14:E14) -> 2
A15: TIMIDOS | C15: CALADO BLUSA/SUETER | D15: BEIGE | E15: 1 | F15: =SUM(E15:E15) -> 1
A16: TIMIDOS | C16: CALADO BLUSA/SUETER | D16: HUESO | E16: 2 | F16: =SUM(E16:E16) -> 2
A17: TIMIDOS | C17: CALADO BLUSA/SUETER | D17: BLANCO | E17: 1 | F17: =SUM(E17:E17) -> 1
A18: TIMIDOS | C18: CALADO BLUSA/SUETER | D18: MALVA | E18: 2 | F18: =SUM(E18:E18) -> 2
A19: TIMIDOS | C19: CALADO BLUSA/SUETER | D19: FRESA | E19: 1 | F19: =SUM(E19:E19) -> 1
A20: TIMIDOS | C20: CALADO BLUSA/SUETER | D20: CAMOTE | E20: 2 | F20: =SUM(E20:E20) -> 2 | G20: =SUM(F11:F20) -> 16
A21: MONJES | C21: MONJES BLUS/SUETER | D21: BLANCO | E21: 1 | F21: =SUM(E21:E21) -> 1
A22: MONJES | C22: MONJES BLUS/SUETER | D22: GRIS CLARO | E22: 1 | F22: =SUM(E22:E22) -> 1
A23: MONJES | C23: MONJES BLUS/SUETER | D23: MARINO | E23: 1 | F23: =SUM(E23:E23) -> 1
A24: MONJES | C24: MONJES BLUS/SUETER | D24: NEGRO | E24: 1 | F24: =SUM(E24:E24) -> 1
A25: MONJES | C25: MONJES BLUS/SUETER | D25: OXFORD | E25: 1 | F25: =SUM(E25:E25) -> 1
A26: MONJES | C26: MONJES BLUS/SUETER | D26: PLUMBAGO | E26: 1 | F26: =SUM(E26:E26) -> 1
A27: MONJES | C27: MONJES BLUS/SUETER | D27: CHEDRON | E27: 1 | F27: =SUM(E27:E27) -> 1
A28: MONJES | C28: MONJES BLUS/SUETER | D28: BEIGE | E28: 1 | F28: =SUM(E28:E28) -> 1
A29: MONJES | C29: MONJES BLUS/SUETER | D29: LILA | E29: 1 | F29: =SUM(E29:E29) -> 1
A30: MONJES | C30: MONJES BLUS/SUETER | D30: UVA | E30: 1 | F30: =SUM(E30:E30) -> 1
A31: MONJES | C31: MONJES BLUS/SUETER | D31: MALVA | E31: 1 | F31: =SUM(E31:E31) -> 1
A32: MONJES | C32: MONJES BLUS/SUETER | D32: PETROLEO | E32: 1 | F32: =SUM(E32:E32) -> 1
A33: MONJES | C33: MONJES BLUS/SUETER | D33: CAKI | E33: 1 | F33: =SUM(E33:E33) -> 1 | G33: NO HAY ARRIBA
A34: MONJES | C34: MONJES BLUS/SUETER | D34: CAMEL | E34: 1 | F34: =SUM(E34:E34) -> 1 | G34: =SUM(F21:F34) -> 14
A35: ODRE | C35: BORDADO BLUS/SUETER | D35: MARINO | E35: 1 | F35: =SUM(E35:E35) -> 1
A36: ODRE | C36: BORDADO BLUS/SUETER | D36: NEGRO | E36: 1 | F36: =SUM(E36:E36) -> 1
A37: ODRE | C37: BORDADO BLUS/SUETER | D37: BEIGE | E37: 1 | F37: =SUM(E37:E37) -> 1
A38: ODRE | C38: BORDADO BLUS/SUETER | D38: GRIS | E38: 1 | F38: =SUM(E38:E38) -> 1 | G38: NO HAY ARRIBA
A39: ODRE | C39: BORDADO BLUS/SUETER | D39: CAKI | E39: 1 | F39: =SUM(E39:E39) -> 1 | G39: =SUM(F35:F39) -> 5
E40: 0 | F40: =SUM(E40:E40) -> 0
...

Sheet SUETER CH G
A1: PROVEEDOR | B1: CODIGO | C1: CARACTERISTICA | D1: COLOR | E1: CH | F1: G | G1: TT UNIDADES
A2: SEX | B2: 006 | C2: BOTON ML | D2: NEGRO | E2: 0 | F2: 3 | G2: =E2+F2 -> 3
A3: SEX | B3: 006 | C3: BOTON ML | D3: MARINO | E3: 0 | F3: 3 | G3: =E3+F3 -> 3
A4: SEX | B4: 006 | C4: BOTON ML | D4: GRIS CLARO | E4: 0 | F4: 1 | G4: =E4+F4 -> 1
A5: SEX | B5: 006 | C5: BOTON ML | D5: OXFORD | E5: 0 | F5: 1 | G5: =E5+F5 -> 1
A6: SEX | B6: 006 | C6: BOTON ML | D6: BLANCO | E6: 0 | F6: 1 | G6: =E6+F6 -> 1
A7: SEX | B7: 006 | C7: BOTON ML | D7: ROSA CLARO | E7: 0 | F7: 1 | G7: =E7+F7 -> 1
A8: SEX | B8: 006 | C8: BOTON ML | D8: ROSA MEDIO | E8: 0 | F8: 2 | G8: =E8+F8 -> 2
A9: SEX | B9: 006 | C9: BOTON ML | D9: CAMOTE | E9: 0 | F9: 2 | G9: =E9+F9 -> 2
A10: SEX | B10: 006 | C10: BOTON ML | D10: CAFE | E10: 0 | F10: 2 | G10: =E10+F10 -> 2
A11: SEX | B11: 006 | C11: BOTON ML | D11: ROJO | E11: 0 | F11: 2 | G11: =E11+F11 -> 2 | H11: =SUM(G2:G11) -> 18
A12: SEX | B12: 034 | C12: M L | D12: MARINO | E12: 7 | F12: 0 | G12: =E12+F12 -> 7
A13: SEX | B13: 034 | C13: M L | D13: GRIS CLARO | E13: 2 | F13: 0 | G13: =E13+F13 -> 2
A14: SEX | B14: 034 | C14: M L | D14: BOTELLA | E14: 1 | F14: 0 | G14: =E14+F14 -> 1
A15: SEX | B15: 034 | C15: M L | D15: CIELO | E15: 3 | F15: 0 | G15: =E15+F15 -> 3
A16: SEX | B16: 034 | C16: M L | D16: BEIGE | E16: 2 | F16: 0 | G16: =E16+F16 -> 2
A17: SEX | B17: 034 | C17: M L | D17: ARENA | E17: 4 | F17: 0 | G17: =E17+F17 -> 4
A18: SEX | B18: 034 | C18: M L | D18: BLANCO | E18: 1 | F18: 0 | G18: =E18+F18 -> 1
A19: SEX | B19: 034 | C19: M L | D19: ROSA CLARO | E19: 2 | F19: 0 | G19: =E19+F19 -> 2
A20: SEX | B20: 034 | C20: M L | D20: ROSA MEDIO | E20: 1 | F20: 0 | G20: =E20+F20 -> 1
A21: SEX | B21: 034 | C21: M L | D21: CAMOTE | E21: 0 | F21: 0 | G21: =E21+F21 -> 0
A22: SEX | B22: 034 | C22: M L | D22: ROJO | E22: 3 | F22: 0 | G22: =E22+F22 -> 3
A23: SEX | B23: 034 | C23: M L | D23: OXFORD | E23: 2 | F23: 0 | G23: =E23+F23 -> 2
A24: SEX | B24: 034 | C24: M L | D24: NEGRO | E24: 5 | F24: 0 | G24: =E24+F24 -> 5 | H24: =SUM(G12:G24) -> 33
A25: SEX | B25: 006-MC | C25: BOTON MC | D25: NEGRO | E25: 0 | F25: 2 | G25: =E25+F25 -> 2
A26: SEX | B26: 006-MC | C26: BOTON MC | D26: BLANCO | E26: 0 | F26: 1 | G26: =E26+F26 -> 1
A27: SEX | B27: 006-MC | C27: BOTON MC | D27: MARINO | E27: 0 | F27: 2 | G27: =E27+F27 -> 2
A28: SEX | B28: 006-MC | C28: BOTON MC | D28: GRIS | E28: 0 | F28: 1 | G28: =E28+F28 -> 1
A29: SEX | B29: 006-MC | C29: BOTON MC | D29: CAFE | E29: 0 | F29: 0 | G29: =E29+F29 -> 0
A30: SEX | B30: 006-MC | C30: BOTON MC | D30: CIELO | E30: 0 | F30: 1 | G30: =E30+F30 -> 1 | H30: =SUM(G25:G30) -> 7
A31: SEX | B31: 007 | C31: CHALECO | D31: NEGRO | E31: 0 | F31: 1 | G31: =E31+F31 -> 1
A32: SEX | B32: 007 | C32: CHALECO | D32: GRIS CLARO | E32: 0 | F32: 2 | G32: =E32+F32 -> 2
A33: SEX | B33: 007 | C33: CHALECO | D33: OXFORD | E33: 0 | F33: 2 | G33: =E33+F33 -> 2
A34: SEX | B34: 007 | C34: CHALECO | D34: MARINO | E34: 0 | F34: 2 | G34: =E34+F34 -> 2
A35: SEX | B35: 007 | C35: CHALECO | D35: CAMEL | E35: 0 | F35: 1 | G35: =E35+F35 -> 1
A36: SEX | B36: 007 | C36: CHALECO | D36: BEIGE | E36: 0 | F36: 3 | G36: =E36+F36 -> 3
A37: SEX | B37: 007 | C37: CHALECO | D37: ROJO | E37: 0 | F37: 1 | G37: =E37+F37 -> 1
A38: SEX | B38: 007 | C38: CHALECO | D38: CAFE | E38: 0 | F38: 1 | G38: =E38+F38 -> 1
A39: SEX | B39: 007 | C39: CHALECO | D39: BLANCO | E39: 0 | F39: 2 | G39: =E39+F39 -> 2
A40: SEX | B40: 007 | C40: CHALECO | D40: ROSA | E40: 0 | F40: 2 | G40: =E40+F40 -> 2 | H40: =SUM(G31:G40) -> 17
...

Sheet FALDA TALLAS
A1: PROVEEDOR | B1: CODIGO | C1: CARACTERISTICA | D1: COLOR | E1: 30 | F1: 32 | G1: 34 | H1: 36 | I1: 38 | J1: 40 | K1: 42 | L1: 44 | M1: 46 | N1: 48 | O1: TT UNIDADES
A2: CAROL | B2: CAROL 01 | C2: FALDA C/HOJAS | D2: VERDE | E2: 0 | F2: 0 | G2: 2 | H2: 5 | I2: 5 | J2: 0 | K2: 0 | L2: 0 | M2: 0 | N2: 0 | O2: =SUM(E2:N2) -> 12 | P2: =O2 -> 12
A3: SCAREN | B3: SCAREN 01 | C3: FALDA PRETINA | D3: NEGRO | E3: 6 | F3: 3 | G3: 4 | H3: 4 | I3: 2 | J3: 5 | K3: 5 | L3: 0 | M3: 0 | N3: 0 | O3: =SUM(E3:N3) -> 29
A4: SCAREN | B4: SCAREN 01 | C4: FALDA PRETINA | D4: GRIS MEDIO | E4: 4 | F4: 7 | G4: 10 | H4: 2 | I4: 0 | J4: 1 | K4: 1 | L4: 0 | M4: 0 | N4: 0 | O4: =SUM(E4:N4) -> 25
A5: SCAREN | B5: SCAREN 01 | C5: FALDA PRETINA | D5: OXFORD | E5: 4 | F5: 8 | G5: 6 | H5: 3 | I5: 2 | J5: 4 | K5: 0 | L5: 0 | M5: 0 | N5: 0 | O5: =SUM(E5:N5) -> 27
A6: SCAREN | B6: SCAREN 01 | C6: FALDA PRETINA | D6: MARINO | E6: 5 | F6: 7 | G6: 3 | H6: 2 | I6: 2 | J6: 0 | K6: 3 | L6: 0 | M6: 0 | N6: 0 | O6: =SUM(E6:N6) -> 22
A7: SCAREN | B7: SCAREN 01 | C7: FALDA PRETINA | D7: PETROLEO | E7: 0 | F7: 2 | G7: 2 | H7: 0 | I7: 0 | J7: 0 | K7: 0 | L7: 0 | M7: 0 | N7: 0 | O7: =SUM(E7:N7) -> 4
A8: SCAREN | B8: SCAREN 01 | C8: FALDA PRETINA | D8: FRANCIA | E8: 0 | F8: 4 | G8: 1 | H8: 0 | I8: 0 | J8: 0 | K8: 0 | L8: 0 | M8: 0 | N8: 0 | O8: =SUM(E8:N8) -> 5
A9: SCAREN | B9: SCAREN 01 | C9: FALDA PRETINA | D9: CIELO | E9: 0 | F9: 4 | G9: 5 | H9: 6 | I9: 4 | J9: 0 | K9: 2 | L9: 0 | M9: 0 | N9: 0 | O9: =SUM(E9:N9) -> 21
A10: SCAREN | B10: SCAREN 01 | C10: FALDA PRETINA | D10: MILITAR | E10: 0 | F10: 5 | G10: 5 | H10: 1 | I10: 2 | J10: 0 | K10: 0 | L10: 0 | M10: 0 | N10: 0 | O10: =SUM(E10:N10) -> 13
A11: SCAREN | B11: SCAREN 01 | C11: FALDA PRETINA | D11: JADE | E11: 0 | F11: 1 | G11: 0 | H11: 0 | I11: 0 | J11: 0 | K11: 0 | L11: 0 | M11: 0 | N11: 0 | O11: =SUM(E11:N11) -> 1
A12: SCAREN | B12: SCAREN 01 | C12: FALDA PRETINA | D12: MANZANA | E12: 1 | F12: 3 | G12: 1 | H12: 0 | I12: 0 | J12: 0 | K12: 0 | L12: 0 | M12: 0 | N12: 0 | O12: =SUM(E12:N12) -> 5
A13: SCAREN | B13: SCAREN 01 | C13: FALDA PRETINA | D13: UVA | E13: 2 | F13: 4 | G13: 3 | H13: 0 | I13: 3 | J13: 0 | K13: 0 | L13: 0 | M13: 0 | N13: 0 | O13: =SUM(E13:N13) -> 12
A14: SCAREN | B14: SCAREN 01 | C14: FALDA PRETINA | D14: PALO | E14: 1 | F14: 5 | G14: 1 | H14: 0 | I14: 2 | J14: 0 | K14: 0 | L14: 0 | M14: 0 | N14: 0 | O14: =SUM(E14:N14) -> 9
... A22: SCAREN | B22: SCAREN 01 | C22: FALDA PRETINA | D22: BEIGE | E22: 1 | F22: 0 | G22: 3 | H22: 3 | I22: 4 | J22: 0 | K22: 2 | L22: 0 | M22: 0 | N22: 0 | O22: =SUM(E22:N22) -> 13
A23: SCAREN | B23: SCAREN 01 | C23: FALDA PRETINA | D23: BLANCO | E23: 0 | F23: 1 | G23: 4 | H23: 3 | I23: 3 | J23: 4 | K23: 4 | L23: 0 | M23: 0 | N23: 0 | O23: =SUM(E23:N23) -> 19 | P23: =SUM(O3:O23) -> 259
E24: =SUM(E2:E23) -> 28 | F24: =SUM(F2:F23) -> 74 | G24: =SUM(G2:G23) -> 61 | H24: =SUM(H2:H23) -> 36 | I24: =SUM(I2:I23) -> 36 | J24: =SUM(J2:J23) -> 16 | K24: =SUM(K2:K23) -> 20 | L24: =SUM(L2:L23) -> 0 | ... P24: =SUM(P2:P23) -> 271

Sheet UNITALLA FALVEST
A1: PROVEEDOR | B1: CODIGO | C1: CARACTERISTICA | D1: COLOR | E1: UNITALLA | F1: TT UNIDADES
A2: EVIER | B2: EVIER 01 | C2: FALDA PELO CONEJO | D2: BEIGE | E2: 3 | F2: =E2 -> 3
A3: EVIER | B3: EVIER 01 | C3: FALDA PELO CONEJO | D3: LILA | E3: 2 | F3: =E3 -> 2
A4: EVIER | B4: EVIER 01 | C4: FALDA PELO CONEJO | D4: ROSA | E4: 2 | F4: =E4 -> 2
A5: EVIER | B5: EVIER 01 | C5: FALDA PELO CONEJO | D5: ROJO | E5: 3 | F5: =E5 -> 3
A6: EVIER | B6: EVIER 01 | C6: FALDA PELO CONEJO | D6: MILITAR | E6: 2 | F6: =E6 -> 2
A7: EVIER | B7: EVIER 01 | C7: FALDA PELO CONEJO | D7: OXFORD | E7: 2 | F7: =E7 -> 2
A8: EVIER | B8: EVIER 01 | C8: FALDA PELO CONEJO | D8: PERLA | E8: 3 | F8: =E8 -> 3
A9: EVIER | B9: EVIER 01 | C9: FALDA PELO CONEJO | D9: CIELO | E9: 2 | F9: =E9 -> 2
A10: EVIER | B10: EVIER 01 | C10: FALDA PELO CONEJO | D10: VINO | E10: 2 | F10: =E10 -> 2
A11: EVIER | B11: EVIER 01 | C11: FALDA PELO CONEJO | D11: CAKI | E11: 3 | F11: =E11 -> 3
A12: EVIER | B12: EVIER 01 | C12: FALDA PELO CONEJO | D12: NEGRO | E12: 2 | F12: =E12 -> 2
A13: EVIER | B13: EVIER 01 | C13: FALDA PELO CONEJO | D13: MARINO | E13: 1 | F13: =E13 -> 1 | G13: =SUM(F2:F13) -> 27
A14: SEX | B14: 203 | C14: VESTIDO TABLEADO | D14: BOTELLA | E14: 1 | F14: =SUM(D14:E14) -> 1
A15: SEX | B15: 203 | C15: VESTIDO TABLEADO | D15: ROJO | E15: 2 | F15: =SUM(D15:E15) -> 2
A16: SEX | B16: 203 | C16: VESTIDO TABLEADO | D16: NEGRO | E16: 2 | F16: =SUM(D16:E16) -> 2
A17: SEX | B17: 203 | C17: VESTIDO TABLEADO | D17: CAKI | E17: 1 | F17: =SUM(D17:E17) -> 1
A18: SEX | B18: 203 | C18: VESTIDO TABLEADO | D18: MILITAR | E18: 1 | F18: =SUM(D18:E18) -> 1
A19: SEX | B19: 203 | C19: VESTIDO TABLEADO | D19: MARINO | E19: 1 | F19: =SUM(D19:E19) -> 1
A20: SEX | B20: 203 | C20: VESTIDO TABLEADO | D20: BEIGE | E20: 1 | F20: =SUM(D20:E20) -> 1
A21: SEX | B21: 203 | C21: VESTIDO TABLEADO | D21: ARENA | E21: 1 | F21: =SUM(D21:E21) -> 1
A22: SEX | B22: 203 | C22: VESTIDO TABLEADO | D22: PALO | E22: 1 | F22: =SUM(D22:E22) -> 1
A23: SEX | B23: 203 | C23: VESTIDO TABLEADO | D23: PIZARRA | E23: 1 | F23: =SUM(D23:E23) -> 1 | G23: =SUM(F14:F23) -> 12
A24: SEX | B24: 178 | C24: VESTIDO CUADROS | D24: KELLI | E24: 2 | F24: =SUM(D24:E24) -> 2
A25: SEX | B25: 178 | C25: VESTIDO CUADROS | D25: CAKI | E25: 1 | F25: =SUM(D25:E25) -> 1
A26: SEX | B26: 178 | C26: VESTIDO CUADROS | D26: PALO | E26: 1 | F26: =SUM(D26:E26) -> 1
A27: SEX | B27: 178 | C27: VESTIDO CUADROS | D27: BEIGE | E27: 1 | F27: =SUM(D27:E27) -> 1
A28: SEX | B28: 178 | C28: VESTIDO CUADROS | D28: MARINO | E28: 1 | F28: =SUM(D28:E28) -> 1
A29: SEX | B29: 178 | C29: VESTIDO CUADROS | D29: ROJO | E29: 1 | F29: =SUM(D29:E29) -> 1 | G29: =SUM(F24:F29) -> 7
A30: MILEORE | B30: 2537 | C30: VESTIDO 2 BOTONES HOMBRO | D30: PIZARRA | E30: 1 | F30: =SUM(E30:E30) -> 1
A31: MILEORE | B31: 2537 | C31: VESTIDO 2 BOTONES HOMBRO | D31: GRIS | E31: 1 | F31: =SUM(E31:E31) -> 1
A32: MILEORE | B32: 2537 | C32: VESTIDO 2 BOTONES HOMBRO | D32: CAMEL | E32: 1 | F32: =SUM(E32:E32) -> 1
A33: MILEORE | B33: 2537 | C33: VESTIDO 2 BOTONES HOMBRO | D33: CHEDRON | E33: 1 | F33: =SUM(E33:E33) -> 1 | G33: =SUM(F30:F33) -> 4
A34: DOMIL | C34: VESTIDO 2 BOTONES MANGA | D34: ROJO | E34: 1 | F34: =SUM(E34:E34) -> 1
A35: DOMIL | C35: VESTIDO 2 BOTONES MANGA | D35: NEGRO | E35: 1 | F35: =SUM(E35:E35) -> 1 | G35: =SUM(F34:F35) -> 2 | H35: =G33+G35+G29+G23 -> 25
E36: =SUM(E2:E35) -> 52 | G36: =SUM(G2:G35) -> 52

Sheet COORD TELA TALLAS
A1: PROVEEDOR | B1: CODIGO | C1: CARACTERISTICA | D1: COLOR | E1: 30 | F1: 32 | G1: 34 | H1: 36 | I1: 38 | J1: 40 | K1: 42 | L1: 44 | M1: 46 | N1: 48 | O1: TT UNIDADES
A2: JESSICA | B2: 1724 | C2: VESTIDO RAYADO H C/SACO | D2: VINO | F2: 2 | G2: 0 | H2: 0 | I2: 0 | J2: 0 | K2: 0 | L2: 0 | M2: 0 | N2: 0 | O2: =SUM(F2:N2) -> 2
A3: JESSICA | B3: 1724 | C3: VESTIDO RAYADO H C/SACO | D3: MARINO | F3: 1 | G3: 0 | H3: 0 | I3: 0 | J3: 0 | K3: 0 | L3: 0 | M3: 0 | N3: 0 | O3: =SUM(F3:N3) -> 1
A4: JESSICA | B4: 1724 | C4: VESTIDO RAYADO H C/SACO | D4: ROJO | F4: 1 | G4: 0 | H4: 0 | I4: 0 | J4: 0 | K4: 0 | L4: 0 | M4: 0 | N4: 0 | O4: =SUM(F4:N4) -> 1
A5: JESSICA | B5: 1724 | C5: VESTIDO RAYADO H C/SACO | D5: NEGRO | F5: 1 | G5: 2 | H5: 1 | I5: 0 | J5: 0 | K5: 0 | L5: 0 | M5: 0 | N5: 0 | O5: =SUM(F5:N5) -> 4 | P5: =SUM(O2:O5) -> 8
A6: JESSICA | B6: 1830 | C6: VESTIDO ESTAMPANDO C/SACO | D6: NEGRO | F6: 0 | G6: 1 | H6: 0 | I6: 1 | J6: 0 | K6: 0 | L6: 0 | M6: 0 | N6: 0 | O6: =SUM(F6:N6) -> 2 | P6: =O6 -> 2
A7: JESSICA | B7: 1919 | C7: VESTIDO LUNARES C/SACO | D7: NEGRO | F7: 0 | G7: 0 | H7: 3 | I7: 0 | J7: 0 | K7: 0 | L7: 0 | M7: 0 | N7: 0 | O7: =SUM(F7:N7) -> 3
A8: JESSICA | B8: 1919 | C8: VESTIDO LUNARES C/SACO | D8: MARINO | F8: 0 | G8: 0 | H8: 1 | I8: 0 | J8: 5 | K8: 0 | L8: 0 | M8: 0 | N8: 0 | O8: =SUM(F8:N8) -> 6 | P8: =O7+O8 -> 9
A9: JESSICA | B9: 1927 | C9: VESTIDO RAYADO V C/SACO | D9: MOSTAZA | F9: 0 | G9: 0 | H9: 0 | I9: 1 | J9: 0 | K9: 0 | L9: 0 | M9: 0 | N9: 0 | O9: =SUM(F9:N9) -> 1 | P9: =O9 -> 1
A10: JESSICA | B10: 1932 | C10: VESTIDO FLOREADO C/SACO | D10: ROJO | F10: 0 | G10: 1 | H10: 0 | I10: 2 | J10: 0 | K10: 0 | L10: 0 | M10: 0 | N10: 0 | O10: =SUM(F10:N10) -> 3 | P10: =O10 -> 3
A11: JESSICA | B11: 1933 | C11: VESTIDO BICOLOR LISO C/SACO | D11: NEGRO HUESO | F11: 2 | G11: 2 | H11: 1 | I11: 2 | J11: 1 | K11: 0 | L11: 0 | M11: 0 | N11: 0 | O11: =SUM(F11:N11) -> 8
A12: JESSICA | B12: 1932 | C12: VESTIDO BICOLOR LISO C/SACO | D12: MARINO HUESO | F12: 1 | G12: 1 | H12: 1 | I12: 4 | J12: 0 | K12: 0 | L12: 0 | M12: 0 | N12: 0 | O12: =SUM(F12:N12) -> 7
A13: JESSICA | B13: 1933 | C13: VESTIDO BICOLOR LISO C/SACO | D13: LILA HUESO | F13: 1 | G13: 0 | H13: 1 | I13: 0 | J13: 0 | K13: 0 | L13: 0 | M13: 0 | N13: 0 | O13: =SUM(F13:N13) -> 2
A14: JESSICA | B14: 1924 | C14: VESTIDO BICOLOR LISO C/SACO | D14: ESMERALDA HUESO | F14: 0 | G14: 1 | H14: 1 | I14: 1 | J14: 2 | K14: 0 | L14: 0 | M14: 0 | N14: 0 | O14: =SUM(F14:N14) -> 5
A15: JESSICA | B15: 1934 | C15: VESTIDO BICOLOR LISO C/SACO | D15: MARINO HUESO | F15: 0 | G15: 1 | H15: 0 | I15: 0 | J15: 0 | K15: 0 | L15: 0 | M15: 0 | N15: 0 | O15: =SUM(F15:N15) -> 1
A16: JESSICA | B16: 1934 | C16: VESTIDO BICOLOR LISO C/SACO | D16: PETROLEO HUESO | F16: 0 | G16: 1 | H16: 0 | I16: 0 | J16: 0 | K16: 0 | L16: 0 | M16: 0 | N16: 0 | O16: =SUM(F16:N16) -> 1 | P16: =SUM(O11:O16) -> 24
A17: JESSICA | B17: 2004 | C17: VESTIDO C/SACO | D17: PALO | F17: 0 | G17: 0 | H17: 0 | I17: 0 | J17: 3 | K17: 0 | L17: 0 | M17: 0 | N17: 0 | O17: =SUM(F17:N17) -> 3
A18: JESSICA | B18: 2004 | C18: VESTIDO C/SACO | D18: OLIVO | F18: 0 | G18: 1 | H18: 1 | I18: 3 | J18: 1 | K18: 0 | L18: 0 | M18: 0 | N18: 0 | O18: =SUM(F18:N18) -> 6
A19: JESSICA | B19: 2004 | C19: VESTIDO C/SACO | D19: FRANCIA | F19: 0 | G19: 1 | H19: 0 | I19: 0 | J19: 0 | K19: 0 | L19: 0 | M19: 0 | N19: 0 | O19: =SUM(F19:N19) -> 1
A20: JESSICA | B20: 2004 | C20: VESTIDO C/SACO | D20: VINO | F20: 0 | G20: 3 | H20: 0 | I20: 3 | J20: 5 | K20: 0 | L20: 0 | M20: 0 | N20: 0 | O20: =SUM(F20:N20) -> 11
A21: JESSICA | B21: 2004 | C21: VESTIDO C/SACO | D21: CHEDRON | F21: 0 | G21: 2 | H21: 0 | I21: 2 | J21: 1 | K21: 0 | L21: 0 | M21: 0 | N21: 0 | O21: =SUM(F21:N21) -> 5
A22: JESSICA | B22: 2004 | C22: VESTIDO C/SACO | D22: MARINO | F22: 0 | G22: 0 | H22: 0 | I22: 0 | J22: 3 | K22: 0 | L22: 0 | M22: 0 | N22: 0 | O22: =SUM(F22:N22) -> 3 | P22: =O17+O18+O19+O20+O21+O22 -> 29 | Q22: =O29-P25 -> 76
A23: JESSICA | B23: 1922 | C23: FALDA BLUSA C/ SACO | D23: NEGRO | F23: 0 | G23: 1 | H23: 1 | I23: 1 | J23: 0 | K23: 0 | L23: 0 | M23: 0 | N23: 0 | O23: =SUM(F23:N23) -> 3
A24: JESSICA | B24: 1922 | C24: FALDA BLUSA C/ SACO | D24: MARINO | F24: 0 | G24: 1 | H24: 1 | I24: 1 | J24: 1 | K24: 0 | L24: 0 | M24: 0 | N24: 0 | O24: =SUM(F24:N24) -> 4
A25: JESSICA | B25: 1922 | C25: FALDA BLUSA C/ SACO | D25: VINO | F25: 0 | G25: 0 | H25: 0 | I25: 1 | J25: 1 | K25: 0 | L25: 0 | M25: 0 | N25: 0 | O25: =SUM(F25:N25) -> 2 | P25: =O23+O24+O25 -> 9
F29: =SUM(F2:F28) -> 9 | G29: =SUM(G2:G28) -> 19 | H29: =SUM(H2:H28) -> 12 | I29: =SUM(I2:I28) -> 22 | J29: =SUM(J2:J28) -> 23 | K29: =SUM(K2:K28) -> 0 | L29: =SUM(L2:L28) -> 0 | M29: =SUM(M2:M28) -> 0 | ... P29: =SUM(P2:P28) -> 85

Sheet Hoja11
